[2023-09-10T17:54:40.781+0000] {taskinstance.py:1157} INFO - Dependencies all met for dep_context=non-requeueable deps ti=<TaskInstance: simple_tasks.exchange_data_task scheduled__2023-09-08T02:00:00+00:00 [queued]>
[2023-09-10T17:54:40.822+0000] {taskinstance.py:1157} INFO - Dependencies all met for dep_context=requeueable deps ti=<TaskInstance: simple_tasks.exchange_data_task scheduled__2023-09-08T02:00:00+00:00 [queued]>
[2023-09-10T17:54:40.823+0000] {taskinstance.py:1359} INFO - Starting attempt 1 of 1
[2023-09-10T17:54:41.573+0000] {taskinstance.py:1380} INFO - Executing <Task(PythonOperator): exchange_data_task> on 2023-09-08 02:00:00+00:00
[2023-09-10T17:54:41.588+0000] {standard_task_runner.py:57} INFO - Started process 260 to run task
[2023-09-10T17:54:41.629+0000] {standard_task_runner.py:84} INFO - Running: ['***', 'tasks', 'run', 'simple_tasks', 'exchange_data_task', 'scheduled__2023-09-08T02:00:00+00:00', '--job-id', '170', '--raw', '--subdir', 'DAGS_FOLDER/script.py', '--cfg-path', '/tmp/tmph8vxqpy_']
[2023-09-10T17:54:41.690+0000] {standard_task_runner.py:85} INFO - Job 170: Subtask exchange_data_task
[2023-09-10T17:54:42.188+0000] {task_command.py:415} INFO - Running <TaskInstance: simple_tasks.exchange_data_task scheduled__2023-09-08T02:00:00+00:00 [running]> on host 3152b479582c
[2023-09-10T17:54:43.380+0000] {taskinstance.py:1660} INFO - Exporting env vars: AIRFLOW_CTX_DAG_OWNER='***' AIRFLOW_CTX_DAG_ID='simple_tasks' AIRFLOW_CTX_TASK_ID='exchange_data_task' AIRFLOW_CTX_EXECUTION_DATE='2023-09-08T02:00:00+00:00' AIRFLOW_CTX_TRY_NUMBER='1' AIRFLOW_CTX_DAG_RUN_ID='scheduled__2023-09-08T02:00:00+00:00'
[2023-09-10T17:54:43.732+0000] {taskinstance.py:1935} ERROR - Task failed with exception
Traceback (most recent call last):
  File "/home/airflow/.local/lib/python3.8/site-packages/airflow/operators/python.py", line 192, in execute
    return_value = self.execute_callable()
  File "/home/airflow/.local/lib/python3.8/site-packages/airflow/operators/python.py", line 209, in execute_callable
    return self.python_callable(*self.op_args, **self.op_kwargs)
  File "/opt/airflow/dags/script.py", line 20, in exchange_data
    connection = psycopg2.connect(
  File "/home/airflow/.local/lib/python3.8/site-packages/psycopg2/__init__.py", line 122, in connect
    conn = _connect(dsn, connection_factory=connection_factory, **kwasync)
psycopg2.OperationalError: connection to server at "localhost" (127.0.0.1), port 5432 failed: Connection refused
	Is the server running on that host and accepting TCP/IP connections?
connection to server at "localhost" (::1), port 5432 failed: Cannot assign requested address
	Is the server running on that host and accepting TCP/IP connections?

[2023-09-10T17:54:43.850+0000] {taskinstance.py:1398} INFO - Marking task as FAILED. dag_id=simple_tasks, task_id=exchange_data_task, execution_date=20230908T020000, start_date=20230910T175440, end_date=20230910T175443
[2023-09-10T17:54:44.473+0000] {standard_task_runner.py:104} ERROR - Failed to execute job 170 for task exchange_data_task (connection to server at "localhost" (127.0.0.1), port 5432 failed: Connection refused
	Is the server running on that host and accepting TCP/IP connections?
connection to server at "localhost" (::1), port 5432 failed: Cannot assign requested address
	Is the server running on that host and accepting TCP/IP connections?
; 260)
[2023-09-10T17:54:44.566+0000] {local_task_job_runner.py:228} INFO - Task exited with return code 1
[2023-09-10T17:54:44.682+0000] {taskinstance.py:2776} INFO - 0 downstream tasks scheduled from follow-on schedule check
[2023-09-11T08:05:58.955+0000] {taskinstance.py:1157} INFO - Dependencies all met for dep_context=non-requeueable deps ti=<TaskInstance: simple_tasks.exchange_data_task scheduled__2023-09-08T02:00:00+00:00 [queued]>
[2023-09-11T08:05:59.006+0000] {taskinstance.py:1157} INFO - Dependencies all met for dep_context=requeueable deps ti=<TaskInstance: simple_tasks.exchange_data_task scheduled__2023-09-08T02:00:00+00:00 [queued]>
[2023-09-11T08:05:59.007+0000] {taskinstance.py:1359} INFO - Starting attempt 1 of 1
[2023-09-11T08:05:59.107+0000] {taskinstance.py:1380} INFO - Executing <Task(PythonOperator): exchange_data_task> on 2023-09-08 02:00:00+00:00
[2023-09-11T08:05:59.142+0000] {standard_task_runner.py:57} INFO - Started process 170 to run task
[2023-09-11T08:05:59.158+0000] {standard_task_runner.py:84} INFO - Running: ['***', 'tasks', 'run', 'simple_tasks', 'exchange_data_task', 'scheduled__2023-09-08T02:00:00+00:00', '--job-id', '21', '--raw', '--subdir', 'DAGS_FOLDER/script.py', '--cfg-path', '/tmp/tmpj2nts1k6']
[2023-09-11T08:05:59.171+0000] {standard_task_runner.py:85} INFO - Job 21: Subtask exchange_data_task
[2023-09-11T08:05:59.569+0000] {task_command.py:415} INFO - Running <TaskInstance: simple_tasks.exchange_data_task scheduled__2023-09-08T02:00:00+00:00 [running]> on host 2c457fbd3561
[2023-09-11T08:06:00.591+0000] {taskinstance.py:1660} INFO - Exporting env vars: AIRFLOW_CTX_DAG_OWNER='***' AIRFLOW_CTX_DAG_ID='simple_tasks' AIRFLOW_CTX_TASK_ID='exchange_data_task' AIRFLOW_CTX_EXECUTION_DATE='2023-09-08T02:00:00+00:00' AIRFLOW_CTX_TRY_NUMBER='1' AIRFLOW_CTX_DAG_RUN_ID='scheduled__2023-09-08T02:00:00+00:00'
[2023-09-11T08:06:00.713+0000] {taskinstance.py:1935} ERROR - Task failed with exception
Traceback (most recent call last):
  File "/home/airflow/.local/lib/python3.8/site-packages/urllib3/connection.py", line 174, in _new_conn
    conn = connection.create_connection(
  File "/home/airflow/.local/lib/python3.8/site-packages/urllib3/util/connection.py", line 72, in create_connection
    for res in socket.getaddrinfo(host, port, family, socket.SOCK_STREAM):
  File "/usr/local/lib/python3.8/socket.py", line 918, in getaddrinfo
    for res in _socket.getaddrinfo(host, port, family, type, proto, flags):
socket.gaierror: [Errno -2] Name or service not known

During handling of the above exception, another exception occurred:

Traceback (most recent call last):
  File "/home/airflow/.local/lib/python3.8/site-packages/urllib3/connectionpool.py", line 714, in urlopen
    httplib_response = self._make_request(
  File "/home/airflow/.local/lib/python3.8/site-packages/urllib3/connectionpool.py", line 403, in _make_request
    self._validate_conn(conn)
  File "/home/airflow/.local/lib/python3.8/site-packages/urllib3/connectionpool.py", line 1053, in _validate_conn
    conn.connect()
  File "/home/airflow/.local/lib/python3.8/site-packages/urllib3/connection.py", line 363, in connect
    self.sock = conn = self._new_conn()
  File "/home/airflow/.local/lib/python3.8/site-packages/urllib3/connection.py", line 186, in _new_conn
    raise NewConnectionError(
urllib3.exceptions.NewConnectionError: <urllib3.connection.HTTPSConnection object at 0x7fdcb99d3a00>: Failed to establish a new connection: [Errno -2] Name or service not known

During handling of the above exception, another exception occurred:

Traceback (most recent call last):
  File "/home/airflow/.local/lib/python3.8/site-packages/requests/adapters.py", line 486, in send
    resp = conn.urlopen(
  File "/home/airflow/.local/lib/python3.8/site-packages/urllib3/connectionpool.py", line 798, in urlopen
    retries = retries.increment(
  File "/home/airflow/.local/lib/python3.8/site-packages/urllib3/util/retry.py", line 592, in increment
    raise MaxRetryError(_pool, url, error or ResponseError(cause))
urllib3.exceptions.MaxRetryError: HTTPSConnectionPool(host='api.exchangerate.host', port=443): Max retries exceeded with url: /latest?base=BTC&symbols=RUB&format=JSON (Caused by NewConnectionError('<urllib3.connection.HTTPSConnection object at 0x7fdcb99d3a00>: Failed to establish a new connection: [Errno -2] Name or service not known'))

During handling of the above exception, another exception occurred:

Traceback (most recent call last):
  File "/home/airflow/.local/lib/python3.8/site-packages/airflow/operators/python.py", line 192, in execute
    return_value = self.execute_callable()
  File "/home/airflow/.local/lib/python3.8/site-packages/airflow/operators/python.py", line 209, in execute_callable
    return self.python_callable(*self.op_args, **self.op_kwargs)
  File "/opt/airflow/dags/script.py", line 19, in exchange_data
    response = requests.get(url, params=params)
  File "/home/airflow/.local/lib/python3.8/site-packages/requests/api.py", line 73, in get
    return request("get", url, params=params, **kwargs)
  File "/home/airflow/.local/lib/python3.8/site-packages/requests/api.py", line 59, in request
    return session.request(method=method, url=url, **kwargs)
  File "/home/airflow/.local/lib/python3.8/site-packages/requests/sessions.py", line 589, in request
    resp = self.send(prep, **send_kwargs)
  File "/home/airflow/.local/lib/python3.8/site-packages/requests/sessions.py", line 703, in send
    r = adapter.send(request, **kwargs)
  File "/home/airflow/.local/lib/python3.8/site-packages/requests/adapters.py", line 519, in send
    raise ConnectionError(e, request=request)
requests.exceptions.ConnectionError: HTTPSConnectionPool(host='api.exchangerate.host', port=443): Max retries exceeded with url: /latest?base=BTC&symbols=RUB&format=JSON (Caused by NewConnectionError('<urllib3.connection.HTTPSConnection object at 0x7fdcb99d3a00>: Failed to establish a new connection: [Errno -2] Name or service not known'))
[2023-09-11T08:06:00.962+0000] {taskinstance.py:1398} INFO - Marking task as FAILED. dag_id=simple_tasks, task_id=exchange_data_task, execution_date=20230908T020000, start_date=20230911T080558, end_date=20230911T080600
[2023-09-11T08:06:01.749+0000] {standard_task_runner.py:104} ERROR - Failed to execute job 21 for task exchange_data_task (HTTPSConnectionPool(host='api.exchangerate.host', port=443): Max retries exceeded with url: /latest?base=BTC&symbols=RUB&format=JSON (Caused by NewConnectionError('<urllib3.connection.HTTPSConnection object at 0x7fdcb99d3a00>: Failed to establish a new connection: [Errno -2] Name or service not known')); 170)
[2023-09-11T08:06:01.810+0000] {local_task_job_runner.py:228} INFO - Task exited with return code 1
[2023-09-11T08:06:01.885+0000] {taskinstance.py:2776} INFO - 0 downstream tasks scheduled from follow-on schedule check
[2023-09-11T08:17:24.565+0000] {taskinstance.py:1157} INFO - Dependencies all met for dep_context=non-requeueable deps ti=<TaskInstance: simple_tasks.exchange_data_task scheduled__2023-09-08T02:00:00+00:00 [queued]>
[2023-09-11T08:17:24.583+0000] {taskinstance.py:1157} INFO - Dependencies all met for dep_context=requeueable deps ti=<TaskInstance: simple_tasks.exchange_data_task scheduled__2023-09-08T02:00:00+00:00 [queued]>
[2023-09-11T08:17:24.584+0000] {taskinstance.py:1359} INFO - Starting attempt 1 of 1
[2023-09-11T08:17:24.617+0000] {taskinstance.py:1380} INFO - Executing <Task(PythonOperator): exchange_data_task> on 2023-09-08 02:00:00+00:00
[2023-09-11T08:17:24.630+0000] {standard_task_runner.py:57} INFO - Started process 170 to run task
[2023-09-11T08:17:24.642+0000] {standard_task_runner.py:84} INFO - Running: ['***', 'tasks', 'run', 'simple_tasks', 'exchange_data_task', 'scheduled__2023-09-08T02:00:00+00:00', '--job-id', '26', '--raw', '--subdir', 'DAGS_FOLDER/script.py', '--cfg-path', '/tmp/tmpa3zd_9dd']
[2023-09-11T08:17:24.656+0000] {standard_task_runner.py:85} INFO - Job 26: Subtask exchange_data_task
[2023-09-11T08:17:24.787+0000] {task_command.py:415} INFO - Running <TaskInstance: simple_tasks.exchange_data_task scheduled__2023-09-08T02:00:00+00:00 [running]> on host 47888c058366
[2023-09-11T08:17:25.528+0000] {taskinstance.py:1660} INFO - Exporting env vars: AIRFLOW_CTX_DAG_OWNER='***' AIRFLOW_CTX_DAG_ID='simple_tasks' AIRFLOW_CTX_TASK_ID='exchange_data_task' AIRFLOW_CTX_EXECUTION_DATE='2023-09-08T02:00:00+00:00' AIRFLOW_CTX_TRY_NUMBER='1' AIRFLOW_CTX_DAG_RUN_ID='scheduled__2023-09-08T02:00:00+00:00'
[2023-09-11T08:17:25.558+0000] {taskinstance.py:1935} ERROR - Task failed with exception
Traceback (most recent call last):
  File "/home/airflow/.local/lib/python3.8/site-packages/urllib3/connection.py", line 174, in _new_conn
    conn = connection.create_connection(
  File "/home/airflow/.local/lib/python3.8/site-packages/urllib3/util/connection.py", line 72, in create_connection
    for res in socket.getaddrinfo(host, port, family, socket.SOCK_STREAM):
  File "/usr/local/lib/python3.8/socket.py", line 918, in getaddrinfo
    for res in _socket.getaddrinfo(host, port, family, type, proto, flags):
socket.gaierror: [Errno -2] Name or service not known

During handling of the above exception, another exception occurred:

Traceback (most recent call last):
  File "/home/airflow/.local/lib/python3.8/site-packages/urllib3/connectionpool.py", line 714, in urlopen
    httplib_response = self._make_request(
  File "/home/airflow/.local/lib/python3.8/site-packages/urllib3/connectionpool.py", line 403, in _make_request
    self._validate_conn(conn)
  File "/home/airflow/.local/lib/python3.8/site-packages/urllib3/connectionpool.py", line 1053, in _validate_conn
    conn.connect()
  File "/home/airflow/.local/lib/python3.8/site-packages/urllib3/connection.py", line 363, in connect
    self.sock = conn = self._new_conn()
  File "/home/airflow/.local/lib/python3.8/site-packages/urllib3/connection.py", line 186, in _new_conn
    raise NewConnectionError(
urllib3.exceptions.NewConnectionError: <urllib3.connection.HTTPSConnection object at 0x7f71fe393bb0>: Failed to establish a new connection: [Errno -2] Name or service not known

During handling of the above exception, another exception occurred:

Traceback (most recent call last):
  File "/home/airflow/.local/lib/python3.8/site-packages/requests/adapters.py", line 486, in send
    resp = conn.urlopen(
  File "/home/airflow/.local/lib/python3.8/site-packages/urllib3/connectionpool.py", line 798, in urlopen
    retries = retries.increment(
  File "/home/airflow/.local/lib/python3.8/site-packages/urllib3/util/retry.py", line 592, in increment
    raise MaxRetryError(_pool, url, error or ResponseError(cause))
urllib3.exceptions.MaxRetryError: HTTPSConnectionPool(host='api.exchangerate.host', port=443): Max retries exceeded with url: /latest?base=BTC&symbols=RUB&format=JSON (Caused by NewConnectionError('<urllib3.connection.HTTPSConnection object at 0x7f71fe393bb0>: Failed to establish a new connection: [Errno -2] Name or service not known'))

During handling of the above exception, another exception occurred:

Traceback (most recent call last):
  File "/home/airflow/.local/lib/python3.8/site-packages/airflow/operators/python.py", line 192, in execute
    return_value = self.execute_callable()
  File "/home/airflow/.local/lib/python3.8/site-packages/airflow/operators/python.py", line 209, in execute_callable
    return self.python_callable(*self.op_args, **self.op_kwargs)
  File "/opt/airflow/dags/script.py", line 20, in exchange_data
    response = requests.get(url, params=params)
  File "/home/airflow/.local/lib/python3.8/site-packages/requests/api.py", line 73, in get
    return request("get", url, params=params, **kwargs)
  File "/home/airflow/.local/lib/python3.8/site-packages/requests/api.py", line 59, in request
    return session.request(method=method, url=url, **kwargs)
  File "/home/airflow/.local/lib/python3.8/site-packages/requests/sessions.py", line 589, in request
    resp = self.send(prep, **send_kwargs)
  File "/home/airflow/.local/lib/python3.8/site-packages/requests/sessions.py", line 703, in send
    r = adapter.send(request, **kwargs)
  File "/home/airflow/.local/lib/python3.8/site-packages/requests/adapters.py", line 519, in send
    raise ConnectionError(e, request=request)
requests.exceptions.ConnectionError: HTTPSConnectionPool(host='api.exchangerate.host', port=443): Max retries exceeded with url: /latest?base=BTC&symbols=RUB&format=JSON (Caused by NewConnectionError('<urllib3.connection.HTTPSConnection object at 0x7f71fe393bb0>: Failed to establish a new connection: [Errno -2] Name or service not known'))
[2023-09-11T08:17:25.642+0000] {taskinstance.py:1398} INFO - Marking task as FAILED. dag_id=simple_tasks, task_id=exchange_data_task, execution_date=20230908T020000, start_date=20230911T081724, end_date=20230911T081725
[2023-09-11T08:17:25.676+0000] {standard_task_runner.py:104} ERROR - Failed to execute job 26 for task exchange_data_task (HTTPSConnectionPool(host='api.exchangerate.host', port=443): Max retries exceeded with url: /latest?base=BTC&symbols=RUB&format=JSON (Caused by NewConnectionError('<urllib3.connection.HTTPSConnection object at 0x7f71fe393bb0>: Failed to establish a new connection: [Errno -2] Name or service not known')); 170)
[2023-09-11T08:17:25.709+0000] {local_task_job_runner.py:228} INFO - Task exited with return code 1
[2023-09-11T08:17:25.872+0000] {taskinstance.py:2776} INFO - 0 downstream tasks scheduled from follow-on schedule check
