[2023-09-12T14:35:18.082+0000] {taskinstance.py:1157} INFO - Dependencies all met for dep_context=non-requeueable deps ti=<TaskInstance: simple_tasks.exchange_data_task scheduled__2023-09-12T14:30:15+00:00 [queued]>
[2023-09-12T14:35:18.097+0000] {taskinstance.py:1157} INFO - Dependencies all met for dep_context=requeueable deps ti=<TaskInstance: simple_tasks.exchange_data_task scheduled__2023-09-12T14:30:15+00:00 [queued]>
[2023-09-12T14:35:18.098+0000] {taskinstance.py:1359} INFO - Starting attempt 1 of 1
[2023-09-12T14:35:18.120+0000] {taskinstance.py:1380} INFO - Executing <Task(PythonOperator): exchange_data_task> on 2023-09-12 14:30:15+00:00
[2023-09-12T14:35:18.132+0000] {standard_task_runner.py:57} INFO - Started process 245 to run task
[2023-09-12T14:35:18.138+0000] {standard_task_runner.py:84} INFO - Running: ['***', 'tasks', 'run', 'simple_tasks', 'exchange_data_task', 'scheduled__2023-09-12T14:30:15+00:00', '--job-id', '38', '--raw', '--subdir', 'DAGS_FOLDER/script.py', '--cfg-path', '/tmp/tmp7gh_ybxo']
[2023-09-12T14:35:18.143+0000] {standard_task_runner.py:85} INFO - Job 38: Subtask exchange_data_task
[2023-09-12T14:35:18.233+0000] {task_command.py:415} INFO - Running <TaskInstance: simple_tasks.exchange_data_task scheduled__2023-09-12T14:30:15+00:00 [running]> on host fbfbca5b9527
[2023-09-12T14:35:18.340+0000] {taskinstance.py:1660} INFO - Exporting env vars: AIRFLOW_CTX_DAG_OWNER='***' AIRFLOW_CTX_DAG_ID='simple_tasks' AIRFLOW_CTX_TASK_ID='exchange_data_task' AIRFLOW_CTX_EXECUTION_DATE='2023-09-12T14:30:15+00:00' AIRFLOW_CTX_TRY_NUMBER='1' AIRFLOW_CTX_DAG_RUN_ID='scheduled__2023-09-12T14:30:15+00:00'
[2023-09-12T14:35:18.618+0000] {taskinstance.py:1935} ERROR - Task failed with exception
Traceback (most recent call last):
  File "/home/airflow/.local/lib/python3.8/site-packages/airflow/operators/python.py", line 192, in execute
    return_value = self.execute_callable()
  File "/home/airflow/.local/lib/python3.8/site-packages/airflow/operators/python.py", line 209, in execute_callable
    return self.python_callable(*self.op_args, **self.op_kwargs)
  File "/opt/airflow/dags/script.py", line 23, in exchange_data
    connection = psycopg2.connect(
  File "/home/airflow/.local/lib/python3.8/site-packages/psycopg2/__init__.py", line 122, in connect
    conn = _connect(dsn, connection_factory=connection_factory, **kwasync)
psycopg2.OperationalError: connection to server at "localhost" (127.0.0.1), port 5432 failed: Connection refused
	Is the server running on that host and accepting TCP/IP connections?
connection to server at "localhost" (::1), port 5432 failed: Cannot assign requested address
	Is the server running on that host and accepting TCP/IP connections?

[2023-09-12T14:35:18.634+0000] {taskinstance.py:1398} INFO - Marking task as FAILED. dag_id=simple_tasks, task_id=exchange_data_task, execution_date=20230912T143015, start_date=20230912T143518, end_date=20230912T143518
[2023-09-12T14:35:18.657+0000] {standard_task_runner.py:104} ERROR - Failed to execute job 38 for task exchange_data_task (connection to server at "localhost" (127.0.0.1), port 5432 failed: Connection refused
	Is the server running on that host and accepting TCP/IP connections?
connection to server at "localhost" (::1), port 5432 failed: Cannot assign requested address
	Is the server running on that host and accepting TCP/IP connections?
; 245)
[2023-09-12T14:35:18.716+0000] {local_task_job_runner.py:228} INFO - Task exited with return code 1
[2023-09-12T14:35:18.806+0000] {taskinstance.py:2776} INFO - 0 downstream tasks scheduled from follow-on schedule check
