[2023-09-12T14:37:48.062+0000] {taskinstance.py:1157} INFO - Dependencies all met for dep_context=non-requeueable deps ti=<TaskInstance: simple_tasks.exchange_data_task scheduled__2023-09-12T14:37:30+00:00 [queued]>
[2023-09-12T14:37:48.069+0000] {taskinstance.py:1157} INFO - Dependencies all met for dep_context=requeueable deps ti=<TaskInstance: simple_tasks.exchange_data_task scheduled__2023-09-12T14:37:30+00:00 [queued]>
[2023-09-12T14:37:48.070+0000] {taskinstance.py:1359} INFO - Starting attempt 1 of 1
[2023-09-12T14:37:48.083+0000] {taskinstance.py:1380} INFO - Executing <Task(PythonOperator): exchange_data_task> on 2023-09-12 14:37:30+00:00
[2023-09-12T14:37:48.088+0000] {standard_task_runner.py:57} INFO - Started process 391 to run task
[2023-09-12T14:37:48.091+0000] {standard_task_runner.py:84} INFO - Running: ['***', 'tasks', 'run', 'simple_tasks', 'exchange_data_task', 'scheduled__2023-09-12T14:37:30+00:00', '--job-id', '72', '--raw', '--subdir', 'DAGS_FOLDER/script.py', '--cfg-path', '/tmp/tmp3xss50df']
[2023-09-12T14:37:48.094+0000] {standard_task_runner.py:85} INFO - Job 72: Subtask exchange_data_task
[2023-09-12T14:37:48.134+0000] {task_command.py:415} INFO - Running <TaskInstance: simple_tasks.exchange_data_task scheduled__2023-09-12T14:37:30+00:00 [running]> on host fbfbca5b9527
[2023-09-12T14:37:48.198+0000] {taskinstance.py:1660} INFO - Exporting env vars: AIRFLOW_CTX_DAG_OWNER='***' AIRFLOW_CTX_DAG_ID='simple_tasks' AIRFLOW_CTX_TASK_ID='exchange_data_task' AIRFLOW_CTX_EXECUTION_DATE='2023-09-12T14:37:30+00:00' AIRFLOW_CTX_TRY_NUMBER='1' AIRFLOW_CTX_DAG_RUN_ID='scheduled__2023-09-12T14:37:30+00:00'
[2023-09-12T14:37:49.139+0000] {logging_mixin.py:151} INFO - Connected
[2023-09-12T14:37:49.140+0000] {taskinstance.py:1935} ERROR - Task failed with exception
Traceback (most recent call last):
  File "/home/airflow/.local/lib/python3.8/site-packages/airflow/operators/python.py", line 192, in execute
    return_value = self.execute_callable()
  File "/home/airflow/.local/lib/python3.8/site-packages/airflow/operators/python.py", line 209, in execute_callable
    return self.python_callable(*self.op_args, **self.op_kwargs)
  File "/opt/airflow/dags/script.py", line 34, in exchange_data
    today = datetime.datetime.today().replace(microsecond=0).strftime('%Y-%m-%d %H:%M:%S')
AttributeError: type object 'datetime.datetime' has no attribute 'datetime'
[2023-09-12T14:37:49.149+0000] {taskinstance.py:1398} INFO - Marking task as FAILED. dag_id=simple_tasks, task_id=exchange_data_task, execution_date=20230912T143730, start_date=20230912T143748, end_date=20230912T143749
[2023-09-12T14:37:49.159+0000] {standard_task_runner.py:104} ERROR - Failed to execute job 72 for task exchange_data_task (type object 'datetime.datetime' has no attribute 'datetime'; 391)
[2023-09-12T14:37:49.191+0000] {local_task_job_runner.py:228} INFO - Task exited with return code 1
[2023-09-12T14:37:49.205+0000] {taskinstance.py:2776} INFO - 0 downstream tasks scheduled from follow-on schedule check
