[2023-09-10T20:10:48.614+0000] {taskinstance.py:1157} INFO - Dependencies all met for dep_context=non-requeueable deps ti=<TaskInstance: simple_tasks.exchange_data_task scheduled__2023-09-08T12:00:00+00:00 [queued]>
[2023-09-10T20:10:48.652+0000] {taskinstance.py:1157} INFO - Dependencies all met for dep_context=requeueable deps ti=<TaskInstance: simple_tasks.exchange_data_task scheduled__2023-09-08T12:00:00+00:00 [queued]>
[2023-09-10T20:10:48.652+0000] {taskinstance.py:1359} INFO - Starting attempt 1 of 1
[2023-09-10T20:10:48.699+0000] {taskinstance.py:1380} INFO - Executing <Task(PythonOperator): exchange_data_task> on 2023-09-08 12:00:00+00:00
[2023-09-10T20:10:48.708+0000] {standard_task_runner.py:57} INFO - Started process 2735 to run task
[2023-09-10T20:10:48.718+0000] {standard_task_runner.py:84} INFO - Running: ['***', 'tasks', 'run', 'simple_tasks', 'exchange_data_task', 'scheduled__2023-09-08T12:00:00+00:00', '--job-id', '289', '--raw', '--subdir', 'DAGS_FOLDER/script.py', '--cfg-path', '/tmp/tmpwwx4f_fu']
[2023-09-10T20:10:48.746+0000] {standard_task_runner.py:85} INFO - Job 289: Subtask exchange_data_task
[2023-09-10T20:10:49.149+0000] {task_command.py:415} INFO - Running <TaskInstance: simple_tasks.exchange_data_task scheduled__2023-09-08T12:00:00+00:00 [running]> on host 3152b479582c
[2023-09-10T20:10:49.623+0000] {taskinstance.py:1660} INFO - Exporting env vars: AIRFLOW_CTX_DAG_OWNER='***' AIRFLOW_CTX_DAG_ID='simple_tasks' AIRFLOW_CTX_TASK_ID='exchange_data_task' AIRFLOW_CTX_EXECUTION_DATE='2023-09-08T12:00:00+00:00' AIRFLOW_CTX_TRY_NUMBER='1' AIRFLOW_CTX_DAG_RUN_ID='scheduled__2023-09-08T12:00:00+00:00'
[2023-09-10T20:10:50.169+0000] {taskinstance.py:1935} ERROR - Task failed with exception
Traceback (most recent call last):
  File "/home/airflow/.local/lib/python3.8/site-packages/airflow/operators/python.py", line 192, in execute
    return_value = self.execute_callable()
  File "/home/airflow/.local/lib/python3.8/site-packages/airflow/operators/python.py", line 209, in execute_callable
    return self.python_callable(*self.op_args, **self.op_kwargs)
  File "/opt/airflow/dags/script.py", line 20, in exchange_data
    connection = psycopg2.connect(
  File "/home/airflow/.local/lib/python3.8/site-packages/psycopg2/__init__.py", line 122, in connect
    conn = _connect(dsn, connection_factory=connection_factory, **kwasync)
psycopg2.OperationalError: connection to server at "localhost" (127.0.0.1), port 5432 failed: Connection refused
	Is the server running on that host and accepting TCP/IP connections?
connection to server at "localhost" (::1), port 5432 failed: Cannot assign requested address
	Is the server running on that host and accepting TCP/IP connections?

[2023-09-10T20:10:50.416+0000] {taskinstance.py:1398} INFO - Marking task as FAILED. dag_id=simple_tasks, task_id=exchange_data_task, execution_date=20230908T120000, start_date=20230910T201048, end_date=20230910T201050
[2023-09-10T20:10:51.347+0000] {standard_task_runner.py:104} ERROR - Failed to execute job 289 for task exchange_data_task (connection to server at "localhost" (127.0.0.1), port 5432 failed: Connection refused
	Is the server running on that host and accepting TCP/IP connections?
connection to server at "localhost" (::1), port 5432 failed: Cannot assign requested address
	Is the server running on that host and accepting TCP/IP connections?
; 2735)
[2023-09-10T20:10:51.567+0000] {local_task_job_runner.py:228} INFO - Task exited with return code 1
[2023-09-10T20:10:51.616+0000] {taskinstance.py:2776} INFO - 0 downstream tasks scheduled from follow-on schedule check
