[2023-09-10T17:56:03.693+0000] {taskinstance.py:1157} INFO - Dependencies all met for dep_context=non-requeueable deps ti=<TaskInstance: simple_tasks.exchange_data_task scheduled__2023-09-08T08:50:00+00:00 [queued]>
[2023-09-10T17:56:03.768+0000] {taskinstance.py:1157} INFO - Dependencies all met for dep_context=requeueable deps ti=<TaskInstance: simple_tasks.exchange_data_task scheduled__2023-09-08T08:50:00+00:00 [queued]>
[2023-09-10T17:56:03.777+0000] {taskinstance.py:1359} INFO - Starting attempt 1 of 1
[2023-09-10T17:56:04.318+0000] {taskinstance.py:1380} INFO - Executing <Task(PythonOperator): exchange_data_task> on 2023-09-08 08:50:00+00:00
[2023-09-10T17:56:04.334+0000] {standard_task_runner.py:57} INFO - Started process 605 to run task
[2023-09-10T17:56:04.385+0000] {standard_task_runner.py:84} INFO - Running: ['***', 'tasks', 'run', 'simple_tasks', 'exchange_data_task', 'scheduled__2023-09-08T08:50:00+00:00', '--job-id', '260', '--raw', '--subdir', 'DAGS_FOLDER/script.py', '--cfg-path', '/tmp/tmp5zb65h65']
[2023-09-10T17:56:04.449+0000] {standard_task_runner.py:85} INFO - Job 260: Subtask exchange_data_task
[2023-09-10T17:56:04.796+0000] {task_command.py:415} INFO - Running <TaskInstance: simple_tasks.exchange_data_task scheduled__2023-09-08T08:50:00+00:00 [running]> on host 3152b479582c
[2023-09-10T17:56:05.350+0000] {taskinstance.py:1660} INFO - Exporting env vars: AIRFLOW_CTX_DAG_OWNER='***' AIRFLOW_CTX_DAG_ID='simple_tasks' AIRFLOW_CTX_TASK_ID='exchange_data_task' AIRFLOW_CTX_EXECUTION_DATE='2023-09-08T08:50:00+00:00' AIRFLOW_CTX_TRY_NUMBER='1' AIRFLOW_CTX_DAG_RUN_ID='scheduled__2023-09-08T08:50:00+00:00'
[2023-09-10T17:56:05.596+0000] {taskinstance.py:1935} ERROR - Task failed with exception
Traceback (most recent call last):
  File "/home/airflow/.local/lib/python3.8/site-packages/airflow/operators/python.py", line 192, in execute
    return_value = self.execute_callable()
  File "/home/airflow/.local/lib/python3.8/site-packages/airflow/operators/python.py", line 209, in execute_callable
    return self.python_callable(*self.op_args, **self.op_kwargs)
  File "/opt/airflow/dags/script.py", line 20, in exchange_data
    connection = psycopg2.connect(
  File "/home/airflow/.local/lib/python3.8/site-packages/psycopg2/__init__.py", line 122, in connect
    conn = _connect(dsn, connection_factory=connection_factory, **kwasync)
psycopg2.OperationalError: connection to server at "localhost" (127.0.0.1), port 5432 failed: Connection refused
	Is the server running on that host and accepting TCP/IP connections?
connection to server at "localhost" (::1), port 5432 failed: Cannot assign requested address
	Is the server running on that host and accepting TCP/IP connections?

[2023-09-10T17:56:05.652+0000] {taskinstance.py:1398} INFO - Marking task as FAILED. dag_id=simple_tasks, task_id=exchange_data_task, execution_date=20230908T085000, start_date=20230910T175603, end_date=20230910T175605
[2023-09-10T17:56:05.689+0000] {standard_task_runner.py:104} ERROR - Failed to execute job 260 for task exchange_data_task (connection to server at "localhost" (127.0.0.1), port 5432 failed: Connection refused
	Is the server running on that host and accepting TCP/IP connections?
connection to server at "localhost" (::1), port 5432 failed: Cannot assign requested address
	Is the server running on that host and accepting TCP/IP connections?
; 605)
[2023-09-10T17:56:05.711+0000] {local_task_job_runner.py:228} INFO - Task exited with return code 1
[2023-09-10T17:56:05.810+0000] {taskinstance.py:2776} INFO - 0 downstream tasks scheduled from follow-on schedule check
