[2023-09-12T14:38:18.525+0000] {taskinstance.py:1157} INFO - Dependencies all met for dep_context=non-requeueable deps ti=<TaskInstance: simple_tasks.exchange_data_task scheduled__2023-09-12T14:38:00+00:00 [queued]>
[2023-09-12T14:38:18.533+0000] {taskinstance.py:1157} INFO - Dependencies all met for dep_context=requeueable deps ti=<TaskInstance: simple_tasks.exchange_data_task scheduled__2023-09-12T14:38:00+00:00 [queued]>
[2023-09-12T14:38:18.534+0000] {taskinstance.py:1359} INFO - Starting attempt 1 of 1
[2023-09-12T14:38:18.549+0000] {taskinstance.py:1380} INFO - Executing <Task(PythonOperator): exchange_data_task> on 2023-09-12 14:38:00+00:00
[2023-09-12T14:38:18.554+0000] {standard_task_runner.py:57} INFO - Started process 413 to run task
[2023-09-12T14:38:18.558+0000] {standard_task_runner.py:84} INFO - Running: ['***', 'tasks', 'run', 'simple_tasks', 'exchange_data_task', 'scheduled__2023-09-12T14:38:00+00:00', '--job-id', '76', '--raw', '--subdir', 'DAGS_FOLDER/script.py', '--cfg-path', '/tmp/tmpb_9qz5q3']
[2023-09-12T14:38:18.561+0000] {standard_task_runner.py:85} INFO - Job 76: Subtask exchange_data_task
[2023-09-12T14:38:18.604+0000] {task_command.py:415} INFO - Running <TaskInstance: simple_tasks.exchange_data_task scheduled__2023-09-12T14:38:00+00:00 [running]> on host fbfbca5b9527
[2023-09-12T14:38:18.679+0000] {taskinstance.py:1660} INFO - Exporting env vars: AIRFLOW_CTX_DAG_OWNER='***' AIRFLOW_CTX_DAG_ID='simple_tasks' AIRFLOW_CTX_TASK_ID='exchange_data_task' AIRFLOW_CTX_EXECUTION_DATE='2023-09-12T14:38:00+00:00' AIRFLOW_CTX_TRY_NUMBER='1' AIRFLOW_CTX_DAG_RUN_ID='scheduled__2023-09-12T14:38:00+00:00'
[2023-09-12T14:38:18.914+0000] {logging_mixin.py:151} INFO - Connected
[2023-09-12T14:38:18.914+0000] {taskinstance.py:1935} ERROR - Task failed with exception
Traceback (most recent call last):
  File "/home/airflow/.local/lib/python3.8/site-packages/airflow/operators/python.py", line 192, in execute
    return_value = self.execute_callable()
  File "/home/airflow/.local/lib/python3.8/site-packages/airflow/operators/python.py", line 209, in execute_callable
    return self.python_callable(*self.op_args, **self.op_kwargs)
  File "/opt/airflow/dags/script.py", line 34, in exchange_data
    today = datetime.datetime.today().replace(microsecond=0).strftime('%Y-%m-%d %H:%M:%S')
AttributeError: type object 'datetime.datetime' has no attribute 'datetime'
[2023-09-12T14:38:18.927+0000] {taskinstance.py:1398} INFO - Marking task as FAILED. dag_id=simple_tasks, task_id=exchange_data_task, execution_date=20230912T143800, start_date=20230912T143818, end_date=20230912T143818
[2023-09-12T14:38:18.938+0000] {standard_task_runner.py:104} ERROR - Failed to execute job 76 for task exchange_data_task (type object 'datetime.datetime' has no attribute 'datetime'; 413)
[2023-09-12T14:38:18.970+0000] {local_task_job_runner.py:228} INFO - Task exited with return code 1
[2023-09-12T14:38:18.984+0000] {taskinstance.py:2776} INFO - 0 downstream tasks scheduled from follow-on schedule check
