[2023-09-10T20:28:24.522+0000] {taskinstance.py:1157} INFO - Dependencies all met for dep_context=non-requeueable deps ti=<TaskInstance: simple_tasks.exchange_data_task scheduled__2023-09-08T16:50:00+00:00 [queued]>
[2023-09-10T20:28:24.599+0000] {taskinstance.py:1157} INFO - Dependencies all met for dep_context=requeueable deps ti=<TaskInstance: simple_tasks.exchange_data_task scheduled__2023-09-08T16:50:00+00:00 [queued]>
[2023-09-10T20:28:24.600+0000] {taskinstance.py:1359} INFO - Starting attempt 1 of 1
[2023-09-10T20:28:24.990+0000] {taskinstance.py:1380} INFO - Executing <Task(PythonOperator): exchange_data_task> on 2023-09-08 16:50:00+00:00
[2023-09-10T20:28:25.100+0000] {standard_task_runner.py:57} INFO - Started process 3204 to run task
[2023-09-10T20:28:25.113+0000] {standard_task_runner.py:84} INFO - Running: ['***', 'tasks', 'run', 'simple_tasks', 'exchange_data_task', 'scheduled__2023-09-08T16:50:00+00:00', '--job-id', '343', '--raw', '--subdir', 'DAGS_FOLDER/script.py', '--cfg-path', '/tmp/tmpv7rqcrby']
[2023-09-10T20:28:25.159+0000] {standard_task_runner.py:85} INFO - Job 343: Subtask exchange_data_task
[2023-09-10T20:28:25.479+0000] {task_command.py:415} INFO - Running <TaskInstance: simple_tasks.exchange_data_task scheduled__2023-09-08T16:50:00+00:00 [running]> on host 3152b479582c
[2023-09-10T20:28:29.573+0000] {taskinstance.py:1660} INFO - Exporting env vars: AIRFLOW_CTX_DAG_OWNER='***' AIRFLOW_CTX_DAG_ID='simple_tasks' AIRFLOW_CTX_TASK_ID='exchange_data_task' AIRFLOW_CTX_EXECUTION_DATE='2023-09-08T16:50:00+00:00' AIRFLOW_CTX_TRY_NUMBER='1' AIRFLOW_CTX_DAG_RUN_ID='scheduled__2023-09-08T16:50:00+00:00'
[2023-09-10T20:28:29.602+0000] {crypto.py:82} WARNING - empty cryptography key - values will not be stored encrypted.
[2023-09-10T20:28:31.016+0000] {taskinstance.py:1935} ERROR - Task failed with exception
Traceback (most recent call last):
  File "/home/airflow/.local/lib/python3.8/site-packages/airflow/operators/python.py", line 192, in execute
    return_value = self.execute_callable()
  File "/home/airflow/.local/lib/python3.8/site-packages/airflow/operators/python.py", line 209, in execute_callable
    return self.python_callable(*self.op_args, **self.op_kwargs)
  File "/opt/airflow/dags/script.py", line 31, in exchange_data
    print("Connected")
  File "/home/airflow/.local/lib/python3.8/site-packages/psycopg2/__init__.py", line 122, in connect
    conn = _connect(dsn, connection_factory=connection_factory, **kwasync)
psycopg2.OperationalError: connection to server at "localhost" (127.0.0.1), port 5432 failed: Connection refused
	Is the server running on that host and accepting TCP/IP connections?
connection to server at "localhost" (::1), port 5432 failed: Cannot assign requested address
	Is the server running on that host and accepting TCP/IP connections?

[2023-09-10T20:28:31.070+0000] {taskinstance.py:1398} INFO - Marking task as FAILED. dag_id=simple_tasks, task_id=exchange_data_task, execution_date=20230908T165000, start_date=20230910T202824, end_date=20230910T202831
[2023-09-10T20:28:31.145+0000] {standard_task_runner.py:104} ERROR - Failed to execute job 343 for task exchange_data_task (connection to server at "localhost" (127.0.0.1), port 5432 failed: Connection refused
	Is the server running on that host and accepting TCP/IP connections?
connection to server at "localhost" (::1), port 5432 failed: Cannot assign requested address
	Is the server running on that host and accepting TCP/IP connections?
; 3204)
[2023-09-10T20:28:31.225+0000] {local_task_job_runner.py:228} INFO - Task exited with return code 1
[2023-09-10T20:28:31.819+0000] {taskinstance.py:2776} INFO - 0 downstream tasks scheduled from follow-on schedule check
