[2023-09-10T17:54:40.578+0000] {taskinstance.py:1157} INFO - Dependencies all met for dep_context=non-requeueable deps ti=<TaskInstance: simple_tasks.exchange_data_task scheduled__2023-09-08T01:40:00+00:00 [queued]>
[2023-09-10T17:54:40.657+0000] {taskinstance.py:1157} INFO - Dependencies all met for dep_context=requeueable deps ti=<TaskInstance: simple_tasks.exchange_data_task scheduled__2023-09-08T01:40:00+00:00 [queued]>
[2023-09-10T17:54:40.671+0000] {taskinstance.py:1359} INFO - Starting attempt 1 of 1
[2023-09-10T17:54:41.539+0000] {taskinstance.py:1380} INFO - Executing <Task(PythonOperator): exchange_data_task> on 2023-09-08 01:40:00+00:00
[2023-09-10T17:54:41.609+0000] {standard_task_runner.py:84} INFO - Running: ['***', 'tasks', 'run', 'simple_tasks', 'exchange_data_task', 'scheduled__2023-09-08T01:40:00+00:00', '--job-id', '167', '--raw', '--subdir', 'DAGS_FOLDER/script.py', '--cfg-path', '/tmp/tmpxme4cj66']
[2023-09-10T17:54:41.626+0000] {standard_task_runner.py:85} INFO - Job 167: Subtask exchange_data_task
[2023-09-10T17:54:41.589+0000] {standard_task_runner.py:57} INFO - Started process 259 to run task
[2023-09-10T17:54:42.076+0000] {task_command.py:415} INFO - Running <TaskInstance: simple_tasks.exchange_data_task scheduled__2023-09-08T01:40:00+00:00 [running]> on host 3152b479582c
[2023-09-10T17:54:43.349+0000] {taskinstance.py:1660} INFO - Exporting env vars: AIRFLOW_CTX_DAG_OWNER='***' AIRFLOW_CTX_DAG_ID='simple_tasks' AIRFLOW_CTX_TASK_ID='exchange_data_task' AIRFLOW_CTX_EXECUTION_DATE='2023-09-08T01:40:00+00:00' AIRFLOW_CTX_TRY_NUMBER='1' AIRFLOW_CTX_DAG_RUN_ID='scheduled__2023-09-08T01:40:00+00:00'
[2023-09-10T17:54:43.677+0000] {taskinstance.py:1935} ERROR - Task failed with exception
Traceback (most recent call last):
  File "/home/airflow/.local/lib/python3.8/site-packages/airflow/operators/python.py", line 192, in execute
    return_value = self.execute_callable()
  File "/home/airflow/.local/lib/python3.8/site-packages/airflow/operators/python.py", line 209, in execute_callable
    return self.python_callable(*self.op_args, **self.op_kwargs)
  File "/opt/airflow/dags/script.py", line 20, in exchange_data
    connection = psycopg2.connect(
  File "/home/airflow/.local/lib/python3.8/site-packages/psycopg2/__init__.py", line 122, in connect
    conn = _connect(dsn, connection_factory=connection_factory, **kwasync)
psycopg2.OperationalError: connection to server at "localhost" (127.0.0.1), port 5432 failed: Connection refused
	Is the server running on that host and accepting TCP/IP connections?
connection to server at "localhost" (::1), port 5432 failed: Cannot assign requested address
	Is the server running on that host and accepting TCP/IP connections?

[2023-09-10T17:54:43.764+0000] {taskinstance.py:1398} INFO - Marking task as FAILED. dag_id=simple_tasks, task_id=exchange_data_task, execution_date=20230908T014000, start_date=20230910T175440, end_date=20230910T175443
[2023-09-10T17:54:43.802+0000] {standard_task_runner.py:104} ERROR - Failed to execute job 167 for task exchange_data_task (connection to server at "localhost" (127.0.0.1), port 5432 failed: Connection refused
	Is the server running on that host and accepting TCP/IP connections?
connection to server at "localhost" (::1), port 5432 failed: Cannot assign requested address
	Is the server running on that host and accepting TCP/IP connections?
; 259)
[2023-09-10T17:54:43.857+0000] {local_task_job_runner.py:228} INFO - Task exited with return code 1
[2023-09-10T17:54:43.961+0000] {taskinstance.py:2776} INFO - 0 downstream tasks scheduled from follow-on schedule check
[2023-09-11T08:06:02.164+0000] {taskinstance.py:1157} INFO - Dependencies all met for dep_context=non-requeueable deps ti=<TaskInstance: simple_tasks.exchange_data_task scheduled__2023-09-08T01:40:00+00:00 [queued]>
[2023-09-11T08:06:02.223+0000] {taskinstance.py:1157} INFO - Dependencies all met for dep_context=requeueable deps ti=<TaskInstance: simple_tasks.exchange_data_task scheduled__2023-09-08T01:40:00+00:00 [queued]>
[2023-09-11T08:06:02.230+0000] {taskinstance.py:1359} INFO - Starting attempt 1 of 1
[2023-09-11T08:06:02.316+0000] {taskinstance.py:1380} INFO - Executing <Task(PythonOperator): exchange_data_task> on 2023-09-08 01:40:00+00:00
[2023-09-11T08:06:02.352+0000] {standard_task_runner.py:57} INFO - Started process 179 to run task
[2023-09-11T08:06:02.369+0000] {standard_task_runner.py:84} INFO - Running: ['***', 'tasks', 'run', 'simple_tasks', 'exchange_data_task', 'scheduled__2023-09-08T01:40:00+00:00', '--job-id', '29', '--raw', '--subdir', 'DAGS_FOLDER/script.py', '--cfg-path', '/tmp/tmpomxyhr65']
[2023-09-11T08:06:02.386+0000] {standard_task_runner.py:85} INFO - Job 29: Subtask exchange_data_task
[2023-09-11T08:06:02.561+0000] {task_command.py:415} INFO - Running <TaskInstance: simple_tasks.exchange_data_task scheduled__2023-09-08T01:40:00+00:00 [running]> on host 2c457fbd3561
[2023-09-11T08:06:02.751+0000] {taskinstance.py:1660} INFO - Exporting env vars: AIRFLOW_CTX_DAG_OWNER='***' AIRFLOW_CTX_DAG_ID='simple_tasks' AIRFLOW_CTX_TASK_ID='exchange_data_task' AIRFLOW_CTX_EXECUTION_DATE='2023-09-08T01:40:00+00:00' AIRFLOW_CTX_TRY_NUMBER='1' AIRFLOW_CTX_DAG_RUN_ID='scheduled__2023-09-08T01:40:00+00:00'
[2023-09-11T08:06:02.774+0000] {taskinstance.py:1935} ERROR - Task failed with exception
Traceback (most recent call last):
  File "/home/airflow/.local/lib/python3.8/site-packages/urllib3/connection.py", line 174, in _new_conn
    conn = connection.create_connection(
  File "/home/airflow/.local/lib/python3.8/site-packages/urllib3/util/connection.py", line 72, in create_connection
    for res in socket.getaddrinfo(host, port, family, socket.SOCK_STREAM):
  File "/usr/local/lib/python3.8/socket.py", line 918, in getaddrinfo
    for res in _socket.getaddrinfo(host, port, family, type, proto, flags):
socket.gaierror: [Errno -2] Name or service not known

During handling of the above exception, another exception occurred:

Traceback (most recent call last):
  File "/home/airflow/.local/lib/python3.8/site-packages/urllib3/connectionpool.py", line 714, in urlopen
    httplib_response = self._make_request(
  File "/home/airflow/.local/lib/python3.8/site-packages/urllib3/connectionpool.py", line 403, in _make_request
    self._validate_conn(conn)
  File "/home/airflow/.local/lib/python3.8/site-packages/urllib3/connectionpool.py", line 1053, in _validate_conn
    conn.connect()
  File "/home/airflow/.local/lib/python3.8/site-packages/urllib3/connection.py", line 363, in connect
    self.sock = conn = self._new_conn()
  File "/home/airflow/.local/lib/python3.8/site-packages/urllib3/connection.py", line 186, in _new_conn
    raise NewConnectionError(
urllib3.exceptions.NewConnectionError: <urllib3.connection.HTTPSConnection object at 0x7fdcb9a1ba60>: Failed to establish a new connection: [Errno -2] Name or service not known

During handling of the above exception, another exception occurred:

Traceback (most recent call last):
  File "/home/airflow/.local/lib/python3.8/site-packages/requests/adapters.py", line 486, in send
    resp = conn.urlopen(
  File "/home/airflow/.local/lib/python3.8/site-packages/urllib3/connectionpool.py", line 798, in urlopen
    retries = retries.increment(
  File "/home/airflow/.local/lib/python3.8/site-packages/urllib3/util/retry.py", line 592, in increment
    raise MaxRetryError(_pool, url, error or ResponseError(cause))
urllib3.exceptions.MaxRetryError: HTTPSConnectionPool(host='api.exchangerate.host', port=443): Max retries exceeded with url: /latest?base=BTC&symbols=RUB&format=JSON (Caused by NewConnectionError('<urllib3.connection.HTTPSConnection object at 0x7fdcb9a1ba60>: Failed to establish a new connection: [Errno -2] Name or service not known'))

During handling of the above exception, another exception occurred:

Traceback (most recent call last):
  File "/home/airflow/.local/lib/python3.8/site-packages/airflow/operators/python.py", line 192, in execute
    return_value = self.execute_callable()
  File "/home/airflow/.local/lib/python3.8/site-packages/airflow/operators/python.py", line 209, in execute_callable
    return self.python_callable(*self.op_args, **self.op_kwargs)
  File "/opt/airflow/dags/script.py", line 19, in exchange_data
    response = requests.get(url, params=params)
  File "/home/airflow/.local/lib/python3.8/site-packages/requests/api.py", line 73, in get
    return request("get", url, params=params, **kwargs)
  File "/home/airflow/.local/lib/python3.8/site-packages/requests/api.py", line 59, in request
    return session.request(method=method, url=url, **kwargs)
  File "/home/airflow/.local/lib/python3.8/site-packages/requests/sessions.py", line 589, in request
    resp = self.send(prep, **send_kwargs)
  File "/home/airflow/.local/lib/python3.8/site-packages/requests/sessions.py", line 703, in send
    r = adapter.send(request, **kwargs)
  File "/home/airflow/.local/lib/python3.8/site-packages/requests/adapters.py", line 519, in send
    raise ConnectionError(e, request=request)
requests.exceptions.ConnectionError: HTTPSConnectionPool(host='api.exchangerate.host', port=443): Max retries exceeded with url: /latest?base=BTC&symbols=RUB&format=JSON (Caused by NewConnectionError('<urllib3.connection.HTTPSConnection object at 0x7fdcb9a1ba60>: Failed to establish a new connection: [Errno -2] Name or service not known'))
[2023-09-11T08:06:02.829+0000] {taskinstance.py:1398} INFO - Marking task as FAILED. dag_id=simple_tasks, task_id=exchange_data_task, execution_date=20230908T014000, start_date=20230911T080602, end_date=20230911T080602
[2023-09-11T08:06:02.886+0000] {standard_task_runner.py:104} ERROR - Failed to execute job 29 for task exchange_data_task (HTTPSConnectionPool(host='api.exchangerate.host', port=443): Max retries exceeded with url: /latest?base=BTC&symbols=RUB&format=JSON (Caused by NewConnectionError('<urllib3.connection.HTTPSConnection object at 0x7fdcb9a1ba60>: Failed to establish a new connection: [Errno -2] Name or service not known')); 179)
[2023-09-11T08:06:02.953+0000] {local_task_job_runner.py:228} INFO - Task exited with return code 1
[2023-09-11T08:06:03.261+0000] {taskinstance.py:2776} INFO - 0 downstream tasks scheduled from follow-on schedule check
[2023-09-11T08:17:21.207+0000] {taskinstance.py:1157} INFO - Dependencies all met for dep_context=non-requeueable deps ti=<TaskInstance: simple_tasks.exchange_data_task scheduled__2023-09-08T01:40:00+00:00 [queued]>
[2023-09-11T08:17:21.266+0000] {taskinstance.py:1157} INFO - Dependencies all met for dep_context=requeueable deps ti=<TaskInstance: simple_tasks.exchange_data_task scheduled__2023-09-08T01:40:00+00:00 [queued]>
[2023-09-11T08:17:21.269+0000] {taskinstance.py:1359} INFO - Starting attempt 1 of 1
[2023-09-11T08:17:21.669+0000] {taskinstance.py:1380} INFO - Executing <Task(PythonOperator): exchange_data_task> on 2023-09-08 01:40:00+00:00
[2023-09-11T08:17:21.718+0000] {standard_task_runner.py:57} INFO - Started process 155 to run task
[2023-09-11T08:17:21.801+0000] {standard_task_runner.py:84} INFO - Running: ['***', 'tasks', 'run', 'simple_tasks', 'exchange_data_task', 'scheduled__2023-09-08T01:40:00+00:00', '--job-id', '21', '--raw', '--subdir', 'DAGS_FOLDER/script.py', '--cfg-path', '/tmp/tmpyg3dec53']
[2023-09-11T08:17:21.850+0000] {standard_task_runner.py:85} INFO - Job 21: Subtask exchange_data_task
[2023-09-11T08:17:22.593+0000] {task_command.py:415} INFO - Running <TaskInstance: simple_tasks.exchange_data_task scheduled__2023-09-08T01:40:00+00:00 [running]> on host 47888c058366
[2023-09-11T08:17:23.013+0000] {taskinstance.py:1660} INFO - Exporting env vars: AIRFLOW_CTX_DAG_OWNER='***' AIRFLOW_CTX_DAG_ID='simple_tasks' AIRFLOW_CTX_TASK_ID='exchange_data_task' AIRFLOW_CTX_EXECUTION_DATE='2023-09-08T01:40:00+00:00' AIRFLOW_CTX_TRY_NUMBER='1' AIRFLOW_CTX_DAG_RUN_ID='scheduled__2023-09-08T01:40:00+00:00'
[2023-09-11T08:17:23.060+0000] {taskinstance.py:1935} ERROR - Task failed with exception
Traceback (most recent call last):
  File "/home/airflow/.local/lib/python3.8/site-packages/urllib3/connection.py", line 174, in _new_conn
    conn = connection.create_connection(
  File "/home/airflow/.local/lib/python3.8/site-packages/urllib3/util/connection.py", line 72, in create_connection
    for res in socket.getaddrinfo(host, port, family, socket.SOCK_STREAM):
  File "/usr/local/lib/python3.8/socket.py", line 918, in getaddrinfo
    for res in _socket.getaddrinfo(host, port, family, type, proto, flags):
socket.gaierror: [Errno -2] Name or service not known

During handling of the above exception, another exception occurred:

Traceback (most recent call last):
  File "/home/airflow/.local/lib/python3.8/site-packages/urllib3/connectionpool.py", line 714, in urlopen
    httplib_response = self._make_request(
  File "/home/airflow/.local/lib/python3.8/site-packages/urllib3/connectionpool.py", line 403, in _make_request
    self._validate_conn(conn)
  File "/home/airflow/.local/lib/python3.8/site-packages/urllib3/connectionpool.py", line 1053, in _validate_conn
    conn.connect()
  File "/home/airflow/.local/lib/python3.8/site-packages/urllib3/connection.py", line 363, in connect
    self.sock = conn = self._new_conn()
  File "/home/airflow/.local/lib/python3.8/site-packages/urllib3/connection.py", line 186, in _new_conn
    raise NewConnectionError(
urllib3.exceptions.NewConnectionError: <urllib3.connection.HTTPSConnection object at 0x7f71fe393970>: Failed to establish a new connection: [Errno -2] Name or service not known

During handling of the above exception, another exception occurred:

Traceback (most recent call last):
  File "/home/airflow/.local/lib/python3.8/site-packages/requests/adapters.py", line 486, in send
    resp = conn.urlopen(
  File "/home/airflow/.local/lib/python3.8/site-packages/urllib3/connectionpool.py", line 798, in urlopen
    retries = retries.increment(
  File "/home/airflow/.local/lib/python3.8/site-packages/urllib3/util/retry.py", line 592, in increment
    raise MaxRetryError(_pool, url, error or ResponseError(cause))
urllib3.exceptions.MaxRetryError: HTTPSConnectionPool(host='api.exchangerate.host', port=443): Max retries exceeded with url: /latest?base=BTC&symbols=RUB&format=JSON (Caused by NewConnectionError('<urllib3.connection.HTTPSConnection object at 0x7f71fe393970>: Failed to establish a new connection: [Errno -2] Name or service not known'))

During handling of the above exception, another exception occurred:

Traceback (most recent call last):
  File "/home/airflow/.local/lib/python3.8/site-packages/airflow/operators/python.py", line 192, in execute
    return_value = self.execute_callable()
  File "/home/airflow/.local/lib/python3.8/site-packages/airflow/operators/python.py", line 209, in execute_callable
    return self.python_callable(*self.op_args, **self.op_kwargs)
  File "/opt/airflow/dags/script.py", line 20, in exchange_data
    response = requests.get(url, params=params)
  File "/home/airflow/.local/lib/python3.8/site-packages/requests/api.py", line 73, in get
    return request("get", url, params=params, **kwargs)
  File "/home/airflow/.local/lib/python3.8/site-packages/requests/api.py", line 59, in request
    return session.request(method=method, url=url, **kwargs)
  File "/home/airflow/.local/lib/python3.8/site-packages/requests/sessions.py", line 589, in request
    resp = self.send(prep, **send_kwargs)
  File "/home/airflow/.local/lib/python3.8/site-packages/requests/sessions.py", line 703, in send
    r = adapter.send(request, **kwargs)
  File "/home/airflow/.local/lib/python3.8/site-packages/requests/adapters.py", line 519, in send
    raise ConnectionError(e, request=request)
requests.exceptions.ConnectionError: HTTPSConnectionPool(host='api.exchangerate.host', port=443): Max retries exceeded with url: /latest?base=BTC&symbols=RUB&format=JSON (Caused by NewConnectionError('<urllib3.connection.HTTPSConnection object at 0x7f71fe393970>: Failed to establish a new connection: [Errno -2] Name or service not known'))
[2023-09-11T08:17:23.164+0000] {taskinstance.py:1398} INFO - Marking task as FAILED. dag_id=simple_tasks, task_id=exchange_data_task, execution_date=20230908T014000, start_date=20230911T081721, end_date=20230911T081723
[2023-09-11T08:17:23.218+0000] {standard_task_runner.py:104} ERROR - Failed to execute job 21 for task exchange_data_task (HTTPSConnectionPool(host='api.exchangerate.host', port=443): Max retries exceeded with url: /latest?base=BTC&symbols=RUB&format=JSON (Caused by NewConnectionError('<urllib3.connection.HTTPSConnection object at 0x7f71fe393970>: Failed to establish a new connection: [Errno -2] Name or service not known')); 155)
[2023-09-11T08:17:23.248+0000] {local_task_job_runner.py:228} INFO - Task exited with return code 1
[2023-09-11T08:17:23.343+0000] {taskinstance.py:2776} INFO - 0 downstream tasks scheduled from follow-on schedule check
