[2023-09-10T17:17:52.209+0000] {taskinstance.py:1157} INFO - Dependencies all met for dep_context=non-requeueable deps ti=<TaskInstance: bash_gm.exchange_data_task scheduled__2023-09-08T00:07:00+00:00 [queued]>
[2023-09-10T17:17:52.246+0000] {taskinstance.py:1157} INFO - Dependencies all met for dep_context=requeueable deps ti=<TaskInstance: bash_gm.exchange_data_task scheduled__2023-09-08T00:07:00+00:00 [queued]>
[2023-09-10T17:17:52.250+0000] {taskinstance.py:1359} INFO - Starting attempt 1 of 1
[2023-09-10T17:17:52.311+0000] {taskinstance.py:1380} INFO - Executing <Task(PythonOperator): exchange_data_task> on 2023-09-08 00:07:00+00:00
[2023-09-10T17:17:52.340+0000] {standard_task_runner.py:57} INFO - Started process 219 to run task
[2023-09-10T17:17:52.355+0000] {standard_task_runner.py:84} INFO - Running: ['***', 'tasks', 'run', 'bash_gm', 'exchange_data_task', 'scheduled__2023-09-08T00:07:00+00:00', '--job-id', '37', '--raw', '--subdir', 'DAGS_FOLDER/script.py', '--cfg-path', '/tmp/tmpj79o9km4']
[2023-09-10T17:17:52.369+0000] {standard_task_runner.py:85} INFO - Job 37: Subtask exchange_data_task
[2023-09-10T17:17:52.569+0000] {task_command.py:415} INFO - Running <TaskInstance: bash_gm.exchange_data_task scheduled__2023-09-08T00:07:00+00:00 [running]> on host 3152b479582c
[2023-09-10T17:17:52.899+0000] {taskinstance.py:1660} INFO - Exporting env vars: AIRFLOW_CTX_DAG_OWNER='***' AIRFLOW_CTX_DAG_ID='bash_gm' AIRFLOW_CTX_TASK_ID='exchange_data_task' AIRFLOW_CTX_EXECUTION_DATE='2023-09-08T00:07:00+00:00' AIRFLOW_CTX_TRY_NUMBER='1' AIRFLOW_CTX_DAG_RUN_ID='scheduled__2023-09-08T00:07:00+00:00'
[2023-09-10T17:17:53.375+0000] {taskinstance.py:1935} ERROR - Task failed with exception
Traceback (most recent call last):
  File "/home/airflow/.local/lib/python3.8/site-packages/airflow/operators/python.py", line 192, in execute
    return_value = self.execute_callable()
  File "/home/airflow/.local/lib/python3.8/site-packages/airflow/operators/python.py", line 209, in execute_callable
    return self.python_callable(*self.op_args, **self.op_kwargs)
  File "/opt/airflow/dags/script.py", line 20, in exchange_data
    connection = psycopg2.connect(
  File "/home/airflow/.local/lib/python3.8/site-packages/psycopg2/__init__.py", line 122, in connect
    conn = _connect(dsn, connection_factory=connection_factory, **kwasync)
psycopg2.OperationalError: connection to server at "localhost" (127.0.0.1), port 5432 failed: Connection refused
	Is the server running on that host and accepting TCP/IP connections?
connection to server at "localhost" (::1), port 5432 failed: Cannot assign requested address
	Is the server running on that host and accepting TCP/IP connections?

[2023-09-10T17:17:53.401+0000] {taskinstance.py:1398} INFO - Marking task as FAILED. dag_id=bash_gm, task_id=exchange_data_task, execution_date=20230908T000700, start_date=20230910T171752, end_date=20230910T171753
[2023-09-10T17:17:53.561+0000] {standard_task_runner.py:104} ERROR - Failed to execute job 37 for task exchange_data_task (connection to server at "localhost" (127.0.0.1), port 5432 failed: Connection refused
	Is the server running on that host and accepting TCP/IP connections?
connection to server at "localhost" (::1), port 5432 failed: Cannot assign requested address
	Is the server running on that host and accepting TCP/IP connections?
; 219)
[2023-09-10T17:17:53.653+0000] {local_task_job_runner.py:228} INFO - Task exited with return code 1
[2023-09-10T17:17:53.746+0000] {taskinstance.py:2776} INFO - 0 downstream tasks scheduled from follow-on schedule check
