[2023-09-10T17:19:36.657+0000] {taskinstance.py:1157} INFO - Dependencies all met for dep_context=non-requeueable deps ti=<TaskInstance: bash_gm.exchange_data_task scheduled__2023-09-08T01:00:00+00:00 [queued]>
[2023-09-10T17:19:36.691+0000] {taskinstance.py:1157} INFO - Dependencies all met for dep_context=requeueable deps ti=<TaskInstance: bash_gm.exchange_data_task scheduled__2023-09-08T01:00:00+00:00 [queued]>
[2023-09-10T17:19:36.695+0000] {taskinstance.py:1359} INFO - Starting attempt 1 of 1
[2023-09-10T17:19:37.678+0000] {taskinstance.py:1380} INFO - Executing <Task(PythonOperator): exchange_data_task> on 2023-09-08 01:00:00+00:00
[2023-09-10T17:19:37.698+0000] {standard_task_runner.py:57} INFO - Started process 554 to run task
[2023-09-10T17:19:37.706+0000] {standard_task_runner.py:84} INFO - Running: ['***', 'tasks', 'run', 'bash_gm', 'exchange_data_task', 'scheduled__2023-09-08T01:00:00+00:00', '--job-id', '123', '--raw', '--subdir', 'DAGS_FOLDER/script.py', '--cfg-path', '/tmp/tmpa6trwe5z']
[2023-09-10T17:19:37.712+0000] {standard_task_runner.py:85} INFO - Job 123: Subtask exchange_data_task
[2023-09-10T17:19:37.844+0000] {task_command.py:415} INFO - Running <TaskInstance: bash_gm.exchange_data_task scheduled__2023-09-08T01:00:00+00:00 [running]> on host 3152b479582c
[2023-09-10T17:19:38.083+0000] {taskinstance.py:1660} INFO - Exporting env vars: AIRFLOW_CTX_DAG_OWNER='***' AIRFLOW_CTX_DAG_ID='bash_gm' AIRFLOW_CTX_TASK_ID='exchange_data_task' AIRFLOW_CTX_EXECUTION_DATE='2023-09-08T01:00:00+00:00' AIRFLOW_CTX_TRY_NUMBER='1' AIRFLOW_CTX_DAG_RUN_ID='scheduled__2023-09-08T01:00:00+00:00'
[2023-09-10T17:19:38.415+0000] {taskinstance.py:1935} ERROR - Task failed with exception
Traceback (most recent call last):
  File "/home/airflow/.local/lib/python3.8/site-packages/airflow/operators/python.py", line 192, in execute
    return_value = self.execute_callable()
  File "/home/airflow/.local/lib/python3.8/site-packages/airflow/operators/python.py", line 209, in execute_callable
    return self.python_callable(*self.op_args, **self.op_kwargs)
  File "/opt/airflow/dags/script.py", line 20, in exchange_data
    connection = psycopg2.connect(
  File "/home/airflow/.local/lib/python3.8/site-packages/psycopg2/__init__.py", line 122, in connect
    conn = _connect(dsn, connection_factory=connection_factory, **kwasync)
psycopg2.OperationalError: connection to server at "localhost" (127.0.0.1), port 5432 failed: Connection refused
	Is the server running on that host and accepting TCP/IP connections?
connection to server at "localhost" (::1), port 5432 failed: Cannot assign requested address
	Is the server running on that host and accepting TCP/IP connections?

[2023-09-10T17:19:38.436+0000] {taskinstance.py:1398} INFO - Marking task as FAILED. dag_id=bash_gm, task_id=exchange_data_task, execution_date=20230908T010000, start_date=20230910T171936, end_date=20230910T171938
[2023-09-10T17:19:38.461+0000] {standard_task_runner.py:104} ERROR - Failed to execute job 123 for task exchange_data_task (connection to server at "localhost" (127.0.0.1), port 5432 failed: Connection refused
	Is the server running on that host and accepting TCP/IP connections?
connection to server at "localhost" (::1), port 5432 failed: Cannot assign requested address
	Is the server running on that host and accepting TCP/IP connections?
; 554)
[2023-09-10T17:19:38.497+0000] {local_task_job_runner.py:228} INFO - Task exited with return code 1
[2023-09-10T17:19:38.529+0000] {taskinstance.py:2776} INFO - 0 downstream tasks scheduled from follow-on schedule check
